Workbook

Sheet Missouri (1)
A1: GEO_ID | B1: STATE_FIPS | C1: CNTY_FIPS | D1: TRACT | E1: CENSUSAREA | F1: STCOFIPS | G1: FIPS | H1: STATE_ABBR | I1: STATE_NAME | J1: COUNTY | K1: LOCATION | L1: TOTPOP | M1: E_TOTPOP | N1: M_TOTPOP | O1: HU | P1: E_HU | Q1: M_HU | R1: HH | S1: E_POV | T1: M_POV | U1: E_UNEMP | V1: M_UNEMP | W1: E_PCI | X1: M_PCI | Y1: E_NOHSDIP | Z1: M_NOHSDIP | AA1: AGE65 | AB1: AGE17 | AC1: SNGPRNT | AD1: MINORITY | AE1: E_LIMENG | AF1: M_LIMENG | AG1: E_MUNIT | AH1: M_MUNIT | AI1: E_MOBILE | AJ1: M_MOBILE | AK1: E_CROWD | AL1: M_CROWD | AM1: E_NOVEH | AN1: M_NOVEH | AO1: GROUPQ | AP1: E_P_POV | AQ1: M_P_POV | AR1: E_P_UNEMP | AS1: M_P_UNEMP | AT1: E_P_PCI | AU1: M_P_PCI | AV1: E_P_NOHSDIP | AW1: M_P_NOHSDIP | AX1: P_AGE65 | AY1: P_AGE17 | AZ1: P_SNGPRNT | BA1: P_MINORITY | BB1: E_P_LIMENG | BC1: M_P_LIMENG | BD1: E_P_MUNIT | BE1: M_P_MUNIT | BF1: E_P_MOBILE | BG1: M_P_MOBILE | BH1: E_P_CROWD | BI1: M_P_CROWD | BJ1: E_P_NOVEH | BK1: M_P_NOVEH | BL1: P_GROUPQ | BM1: E_PL_POV | BN1: E_PL_UNEMP | BO1: E_PL_PCI | BP1: E_PL_NOHSDIP | BQ1: S_PL_THEME1 | BR1: R_PL_THEME1 | BS1: PL_AGE65 | BT1: PL_AGE17 | BU1: PL_SNGPRNT | BV1: S_PL_THEME2 | BW1: R_PL_THEME2 | BX1: PL_MINORITY | BY1: E_PL_LIMENG | BZ1: S_PL_THEME3 | CA1: R_PL_THEME3 | CB1: E_PL_MUNIT | CC1: E_PL_MOBILE | CD1: E_PL_CROWD | CE1: E_PL_NOVEH | CF1: PL_GROUPQ | CG1: S_PL_THEME4 | CH1: R_PL_THEME4 | CI1: S_PL_THEMES | CJ1: R_PL_THEMES | CK1: F_PL_POV | CL1: F_PL_UNEMP | CM1: F_PL_PCI | CN1: F_PL_NOHSDIP | CO1: F_PL_THEME1 | CP1: F_PL_AGE65 | CQ1: F_PL_AGE17 | CR1: F_PL_SNGPRNT | CS1: F_PL_THEME2 | CT1: F_PL_MINORITY | CU1: F_PL_LIMENG | CV1: F_PL_THEME3 | CW1: F_PL_MUNIT | CX1: F_PL_MOBILE | CY1: F_PL_CROWD | CZ1: F_PL_NOVEH | DA1: F_PL_GROUPQ | DB1: F_PL_THEME4 | DC1: F_PL_TOTAL | DD1: Shape | DE1: Shape.STArea() | DF1: Shape.STLength()
A2: 1400000US29001950300 | B2: 29 | C2: 001 | D2: 950300 | E2: 8.134 | F2: 29001 | G2: 29001950300 | H2: MO | I2: Missouri | J2: Adair County | K2: Census Tract 9503, Adair County, Missouri | L2: 2951 | M2: 3138 | N2: 418 | O2: 1615 | P2: 1682 | Q2: 141 | R2: 1388 | S2: 1334 | T2: 472 | U2: 111 | V2: 449 | W2: 12764 | X2: 2246 | Y2: 212 | Z2: 242 | AA2: 269 | AB2: 483 | AC2: 135 | AD2: 277 | AE2: 0 | AF2: 456 | AG2: 223 | AH2: 167 | AI2: 114 | AJ2: 49 | AK2: 10 | AL2: 115 | AM2: 179 | AN2: 108 | AO2: 52 | AP2: 0.425111 | AQ2: 0.139347 | AR2: 0.075613 | AS2: 0.305446 | AT2: 12764 | AU2: 2246 | AV2: 0.131595 | AW2: 0.149503 | AX2: 0.091155 | AY2: 0.163673 | AZ2: 0.09726224 | BA2: 0.093866 | BB2: 0 | BC2: 0.152559 | BD2: 0.13258 | BE2: 0.098662 | BF2: 0.067776 | BG2: 0.028572 | BH2: 0.006775 | BI2: 0.07791 | BJ2: 0.121273 | BK2: 0.072068 | BL2: 0.017621 | BM2: 0.971 | BN2: 0.567 | BO2: 0.9401 | BP2: 0.477 | BQ2: 2.9551 | BR2: 0.7978 | BS2: 0.165 | BT2: 0.089 | BU2: 0.468 | BV2: 0.722 | BW2: 0.061 | BX2: 0.445 | BY2: 0 | BZ2: 0.445 | CA2: 0.187 | CB2: 0.816 | CC2: 0.646 | CD2: 0.384 | CE2: 0.811 | CF2: 0.681 | CG2: 3.338 | CH2: 0.889 | CI2: 7.4601 | CJ2: 0.6325 | CK2: 1 | CL2: 0 | CM2: 1 | CN2: 0 | CO2: 2 | CP2: 0 | CQ2: 0 | CR2: 0 | CS2: 0 | CT2: 0 | CU2: 0 | CV2: 0 | CW2: 0 | CX2: 0 | CY2: 0 | CZ2: 0 | DA2: 0 | DB2: 0 | DC2: 2 | DD2: (-92.61444936593644, 40.22538791173708) | DE2: 0.0022204613 | DF2: 0.3181967762684076
A3: 1400000US29001950400 | B3: 29 | C3: 001 | D3: 950400 | E3: 7.596 | F3: 29001 | G3: 29001950400 | H3: MO | I3: Missouri | J3: Adair County | K3: Census Tract 9504, Adair County, Missouri | L3: 3892 | M3: 4071 | N3: 326 | O3: 1855 | P3: 1798 | Q3: 105 | R3: 1727 | S3: 551 | T3: 195 | U3: 98 | V3: 432 | W3: 22437 | X3: 3061 | Y3: 184 | Z3: 368 | AA3: 663 | AB3: 975 | AC3: 157 | AD3: 237 | AE3: 0 | AF3: 456 | AG3: 92 | AH3: 60 | AI3: 49 | AJ3: 43 | AK3: 4 | AL3: 114 | AM3: 125 | AN3: 59 | AO3: 41 | AP3: 0.13568 | AQ3: 0.046773 | AR3: 0.050882 | AS3: 0.224214 | AT3: 22437 | AU3: 3061 | AV3: 0.068785 | AW3: 0.137489 | AX3: 0.170349 | AY3: 0.250513 | AZ3: 0.09090909 | BA3: 0.060894 | BB3: 0 | BC3: 0.122877 | BD3: 0.051167 | BE3: 0.033236 | BF3: 0.027252 | BG3: 0.023862 | BH3: 0.002318 | BI3: 0.066086 | BJ3: 0.072463 | BK3: 0.033938 | BL3: 0.010534 | BM3: 0.523 | BN3: 0.3 | BO3: 0.4722 | BP3: 0.197 | BQ3: 1.4922 | BR3: 0.3379 | BS3: 0.739 | BT3: 0.602 | BU3: 0.411 | BV3: 1.752 | BW3: 0.684 | BX3: 0.317 | BY3: 0 | BZ3: 0.317 | CA3: 0.135 | CB3: 0.659 | CC3: 0.541 | CD3: 0.286 | CE3: 0.636 | CF3: 0.587 | CG3: 2.709 | CH3: 0.648 | CI3: 6.2702 | CJ3: 0.4217 | CK3: 0 | CL3: 0 | CM3: 0 | CN3: 0 | CO3: 0 | CP3: 0 | CQ3: 0 | CR3: 0 | CS3: 0 | CT3: 0 | CU3: 0 | CV3: 0 | CW3: 0 | CX3: 0 | CY3: 0 | CZ3: 0 | DA3: 0 | DB3: 0 | DC3: 0 | DD3: (-92.56235487893272, 40.21899772397682) | DE3: 0.0020861344 | DF3: 0.2408924972862329
A4: 1400000US29001950100 | B4: 29 | C4: 001 | D4: 950100 | E4: 253.455 | F4: 29001 | G4: 29001950100 | H4: MO | I4: Missouri | J4: Adair County | K4: Census Tract 9501, Adair County, Missouri | L4: 3802 | M4: 3538 | N4: 300 | O4: 1679 | P4: 1708 | Q4: 117 | R4: 1456 | S4: 560 | T4: 213 | U4: 118 | V4: 365 | W4: 20733 | X4: 1993 | Y4: 212 | Z4: 264 | AA4: 553 | AB4: 1046 | AC4: 108 | AD4: 96 | AE4: 37 | AF4: 428 | AG4: 2 | AH4: 161 | AI4: 231 | AJ4: 72 | AK4: 20 | AL4: 20 | AM4: 75 | AN4: 124 | AO4: 0 | AP4: 0.158595 | AQ4: 0.058808 | AR4: 0.069698 | AS4: 0.215453 | AT4: 20733 | AU4: 1993 | AV4: 0.085483 | AW4: 0.106195 | AX4: 0.145449 | AY4: 0.275118 | AZ4: 0.07417582 | BA4: 0.025249 | BB4: 0.011229 | BC4: 0.129889 | BD4: 0.00117 | BE4: 0.094262 | BF4: 0.135245 | BG4: 0.041123 | BH4: 0.014316 | BI4: 0.014264 | BJ4: 0.053686 | BK4: 0.088643 | BL4: 0 | BM4: 0.607 | BN4: 0.512 | BO4: 0.5704 | BP4: 0.272 | BQ4: 1.9614 | BR4: 0.4809 | BS4: 0.543 | BT4: 0.822 | BU4: 0.251 | BV4: 1.616 | BW4: 0.579 | BX4: 0.047 | BY4: 0.753 | BZ4: 0.8 | CA4: 0.4 | CB4: 0.261 | CC4: 0.787 | CD4: 0.579 | CE4: 0.516 | CF4: 0 | CG4: 2.143 | CH4: 0.398 | CI4: 6.5204 | CJ4: 0.4621 | CK4: 0 | CL4: 0 | CM4: 0 | CN4: 0 | CO4: 0 | CP4: 0 | CQ4: 0 | CR4: 0 | CS4: 0 | CT4: 0 | CU4: 0 | CV4: 0 | CW4: 0 | CX4: 0 | CY4: 0 | CZ4: 0 | DA4: 0 | DB4: 0 | DC4: 0 | DD4: (-92.46691577770667, 40.21003710277253) | DE4: 0.06964974 | DF4: 1.3167750375657676
A5: 1400000US29001950200 | B5: 29 | C5: 001 | D5: 950200 | E5: 270.774 | F5: 29001 | G5: 29001950200 | H5: MO | I5: Missouri | J5: Adair County | K5: Census Tract 9502, Adair County, Missouri | L5: 3019 | M5: 3209 | N5: 305 | O5: 1613 | P5: 1550 | Q5: 105 | R5: 1223 | S5: 477 | T5: 289 | U5: 110 | V5: 415 | W5: 19279 | X5: 2215 | Y5: 319 | Z5: 186 | AA5: 510 | AB5: 723 | AC5: 81 | AD5: 66 | AE5: 0 | AF5: 456 | AG5: 0 | AH5: 197 | AI5: 213 | AJ5: 68 | AK5: 75 | AL5: 132 | AM5: 68 | AN5: 47 | AO5: 0 | AP5: 0.148783 | AQ5: 0.089025 | AR5: 0.075342 | AS5: 0.284091 | AT5: 19279 | AU5: 2215 | AV5: 0.1514 | AW5: 0.087215 | AX5: 0.16893 | AY5: 0.239483 | AZ5: 0.06623058 | BA5: 0.021861 | BB5: 0 | BC5: 0.153742 | BD5: 0 | BE5: 0.127096 | BF5: 0.137419 | BG5: 0.042871 | BH5: 0.061274 | BI5: 0.107724 | BJ5: 0.055555 | BK5: 0.038124 | BL5: 0 | BM5: 0.576 | BN5: 0.563 | BO5: 0.652 | BP5: 0.574 | BQ5: 2.365 | BR5: 0.6202 | BS5: 0.728 | BT5: 0.493 | BU5: 0.183 | BV5: 1.404 | BW5: 0.394 | BX5: 0.025 | BY5: 0 | BZ5: 0.025 | CA5: 0.015 | CB5: 0 | CC5: 0.794 | CD5: 0.966 | CE5: 0.536 | CF5: 0 | CG5: 2.296 | CH5: 0.456 | CI5: 6.09 | CJ5: 0.3877 | CK5: 0 | CL5: 0 | CM5: 0 | CN5: 0 | CO5: 0 | CP5: 0 | CQ5: 0 | CR5: 0 | CS5: 0 | CT5: 0 | CU5: 0 | CV5: 0 | CW5: 0 | CX5: 0 | CY5: 1 | CZ5: 0 | DA5: 0 | DB5: 1 | DC5: 1 | DD5: (-92.72531239328066, 40.171508919218084) | DE5: 0.074241067 | DF5: 1.4866251289962238
A6: 1400000US29001950500 | B6: 29 | C6: 001 | D6: 950500 | E6: 26.623 | F6: 29001 | G6: 29001950500 | H6: MO | I6: Missouri | J6: Adair County | K6: Census Tract 9505, Adair County, Missouri | L6: 7079 | M6: 6522 | N6: 510 | O6: 3310 | P6: 3275 | Q6: 169 | R6: 2992 | S6: 1638 | T6: 367 | U6: 207 | V6: 394 | W6: 20377 | X6: 2460 | Y6: 612 | Z6: 228 | AA6: 998 | AB6: 1359 | AC6: 228 | AD6: 590 | AE6: 12 | AF6: 442 | AG6: 197 | AH6: 96 | AI6: 237 | AJ6: 94 | AK6: 74 | AL6: 134 | AM6: 257 | AN6: 97 | AO6: 379 | AP6: 0.265349 | AQ6: 0.055804 | AR6: 0.064687 | AS6: 0.12289 | AT6: 20377 | AU6: 2460 | AV6: 0.156441 | AW6: 0.056841 | AX6: 0.14098 | AY6: 0.191976 | AZ6: 0.0762032 | BA6: 0.083345 | BB6: 0.001937 | BC6: 0.07137 | BD6: 0.060152 | BE6: 0.029148 | BF6: 0.072366 | BG6: 0.028458 | BH6: 0.02659 | BI6: 0.048105 | BJ6: 0.092346 | BK6: 0.034109 | BL6: 0.053538 | BM6: 0.848 | BN6: 0.467 | BO6: 0.5899 | BP6: 0.594 | BQ6: 2.4989 | BR6: 0.6643 | BS6: 0.506 | BT6: 0.158 | BU6: 0.267 | BV6: 0.931 | BW6: 0.094 | BX6: 0.408 | BY6: 0.378 | BZ6: 0.786 | CA6: 0.388 | CB6: 0.685 | CC6: 0.656 | CD6: 0.776 | CE6: 0.728 | CF6: 0.901 | CG6: 3.746 | CH6: 0.982 | CI6: 7.9619 | CJ6: 0.709 | CK6: 0 | CL6: 0 | CM6: 0 | CN6: 0 | CO6: 0 | CP6: 0 | CQ6: 0 | CR6: 0 | CS6: 0 | CT6: 0 | CU6: 0 | CV6: 0 | CW6: 0 | CX6: 0 | CY6: 0 | CZ6: 0 | DA6: 1 | DB6: 1 | DC6: 1 | DD6: (-92.61711932736635, 40.180933183536) | DE6: 0.0075611674 | DF6: 0.5273896290186537
A7: 1400000US29001950900 | B7: 29 | C7: 001 | D7: 950900 | E7: 0.482 | F7: 29001 | G7: 29001950900 | H7: MO | I7: Missouri | J7: Adair County | K7: Census Tract 9509, Adair County, Missouri | L7: 2277 | M7: 2171 | N7: 401 | O7: 1116 | P7: 1173 | Q7: 101 | R7: 1017 | S7: 1108 | T7: 353 | U7: 42 | V7: 472 | W7: 12088 | X7: 2249 | Y7: 86 | Z7: 345 | AA7: 208 | AB7: 373 | AC7: 75 | AD7: 221 | AE7: 0 | AF7: 456 | AG7: 31 | AH7: 118 | AI7: 30 | AJ7: 47 | AK7: 6 | AL7: 114 | AM7: 105 | AN7: 41 | AO7: 0 | AP7: 0.510363 | AQ7: 0.132482 | AR7: 0.033386 | AS7: 0.375038 | AT7: 12088 | AU7: 2249 | AV7: 0.101775 | AW7: 0.407992 | AX7: 0.091348 | AY7: 0.163812 | AZ7: 0.07374631 | BA7: 0.097057 | BB7: 0 | BC7: 0.222439 | BD7: 0.026427 | BE7: 0.100571 | BF7: 0.025575 | BG7: 0.040007 | BH7: 0.006507 | BI7: 0.12364 | BJ7: 0.113882 | BK7: 0.041322 | BL7: 0 | BM7: 0.991 | BN7: 0.114 | BO7: 0.9588 | BP7: 0.346 | BQ7: 2.4098 | BR7: 0.6361 | BS7: 0.166 | BT7: 0.09 | BU7: 0.248 | BV7: 0.504 | BW7: 0.035 | BX7: 0.459 | BY7: 0 | BZ7: 0.459 | CA7: 0.189 | CB7: 0.523 | CC7: 0.534 | CD7: 0.374 | CE7: 0.794 | CF7: 0 | CG7: 2.225 | CH7: 0.428 | CI7: 5.5978 | CJ7: 0.3025 | CK7: 1 | CL7: 0 | CM7: 1 | CN7: 0 | CO7: 2 | CP7: 0 | CQ7: 0 | CR7: 0 | CS7: 0 | CT7: 0 | CU7: 0 | CV7: 0 | CW7: 0 | CX7: 0 | CY7: 0 | CZ7: 0 | DA7: 0 | DB7: 0 | DC7: 2 | DD7: (-92.57430409062717, 40.19471635900403) | DE7: 0.00012996661 | DF7: 0.062437948
A8: 1400000US29001951000 | B8: 29 | C8: 001 | D8: 951000 | E8: 0.26 | F8: 29001 | G8: 29001951000 | H8: MO | I8: Missouri | J8: Adair County | K8: Census Tract 9510, Adair County, Missouri | L8: 2587 | M8: 2666 | N8: 602 | O8: 75 | P8: 57 | Q8: 36 | R8: 74 | S8: 159 | T8: 120 | U8: 12 | V8: 497 | W8: 2659 | X8: 328 | Y8: 0 | Z8: 456 | AA8: 9 | AB8: 13 | AC8: 3 | AD8: 369 | AE8: 0 | AF8: 456 | AG8: 36 | AH8: 118 | AI8: 0 | AJ8: 114 | AK8: 0 | AL8: 161 | AM8: 22 | AN8: 117 | AO8: 2428 | AP8: 1 | AQ8: 0.754716 | AR8: 0.021739 | AS8: 0.900183 | AT8: 2659 | AU8: 328 | AV8: 0 | AW8: 41.454544 | AX8: 0.003478 | AY8: 0.005025 | AZ8: 0.04054054 | BA8: 0.142636 | BB8: 0 | BC8: 0.171042 | BD8: 0.631578 | BE8: 2.031381 | BF8: 0 | BG8: 2 | BH8: 0 | BI8: 2.824561 | BJ8: 0.385964 | BK8: 2.038105 | BL8: 0.938538 | BM8: 1 | BN8: 0.038 | BO8: 1 | BP8: 0 | BQ8: 2.038 | BR8: 0.5112 | BS8: 0.003 | BT8: 0 | BU8: 0.041 | BV8: 0.044 | BW8: 0.004 | BX8: 0.6 | BY8: 0 | BZ8: 0.6 | CA8: 0.269 | CB8: 0.987 | CC8: 0 | CD8: 0 | CE8: 0.982 | CF8: 1 | CG8: 2.969 | CH8: 0.761 | CI8: 5.651 | CJ8: 0.3105 | CK8: 1 | CL8: 0 | CM8: 1 | CN8: 0 | CO8: 2 | CP8: 0 | CQ8: 0 | CR8: 0 | CS8: 0 | CT8: 0 | CU8: 0 | CV8: 0 | CW8: 1 | CX8: 0 | CY8: 0 | CZ8: 1 | DA8: 1 | DB8: 3 | DC8: 5 | DD8: (-92.58058896316552, 40.18519427166938) | DE8: 6.919898337179386e-05 | DF8: 0.03863656
A9: 1400000US29003010100 | B9: 29 | C9: 003 | D9: 010100 | E9: 66.01 | F9: 29003 | G9: 29003010100 | H9: MO | I9: Missouri | J9: Andrew County | K9: Census Tract 101, Andrew County, Missouri | L9: 5439 | M9: 5772 | N9: 311 | O9: 2197 | P9: 2326 | Q9: 103 | R9: 2078 | S9: 509 | T9: 269 | U9: 245 | V9: 271 | W9: 28158 | X9: 2801 | Y9: 299 | Z9: 266 | AA9: 771 | AB9: 1246 | AC9: 146 | AD9: 278 | AE9: 3 | AF9: 442 | AG9: 0 | AH9: 197 | AI9: 265 | AJ9: 106 | AK9: 24 | AL9: 117 | AM9: 90 | AN9: 55 | AO9: 0 | AP9: 0.088184 | AQ9: 0.046361 | AR9: 0.077679 | AS9: 0.085687 | AT9: 28158 | AU9: 2801 | AV9: 0.076081 | AW9: 0.067561 | AX9: 0.141754 | AY9: 0.229086 | AZ9: 0.07025986 | BA9: 0.051112 | BB9: 0.000544 | BC9: 0.080246 | BD9: 0 | BE9: 0.084694 | BF9: 0.113929 | BG9: 0.045291 | BH9: 0.01109 | BI9: 0.054062 | BJ9: 0.041589 | BK9: 0.025307 | BL9: 0 | BM9: 0.331 | BN9: 0.59 | BO9: 0.2462 | BP9: 0.23 | BQ9: 1.3972 | BR9: 0.3105 | BS9: 0.511 | BT9: 0.374 | BU9: 0.217 | BV9: 1.102 | BW9: 0.166 | BX9: 0.255 | BY9: 0.32 | BZ9: 0.575 | CA9: 0.257 | CB9: 0 | CC9: 0.747 | CD9: 0.5 | CE9: 0.408 | CF9: 0 | CG9: 1.655 | CH9: 0.217 | CI9: 4.7292 | CJ9: 0.1639 | CK9: 0 | CL9: 0 | CM9: 0 | CN9: 0 | CO9: 0 | CP9: 0 | CQ9: 0 | CR9: 0 | CS9: 0 | CT9: 0 | CU9: 0 | CV9: 0 | CW9: 0 | CX9: 0 | CY9: 0 | CZ9: 0 | DA9: 0 | DB9: 0 | DC9: 0 | DD9: (-94.75035536815028, 39.855112880975696) | DE9: 0.018213885055663667 | DF9: 0.7463909439122505
A10: 1400000US29003010200 | B10: 29 | C10: 003 | D10: 010200 | E10: 39.012 | F10: 29003 | G10: 29003010200 | H10: MO | I10: Missouri | J10: Andrew County | K10: Census Tract 102, Andrew County, Missouri | L10: 6738 | M10: 6692 | N10: 351 | O10: 2827 | P10: 2760 | Q10: 180 | R10: 2645 | S10: 535 | T10: 195 | U10: 222 | V10: 410 | W10: 21031 | X10: 1431 | Y10: 595 | Z10: 321 | AA10: 1169 | AB10: 1712 | AC10: 308 | AD10: 223 | AE10: 67 | AF10: 413 | AG10: 104 | AH10: 66 | AI10: 235 | AJ10: 103 | AK10: 33 | AL10: 121 | AM10: 60 | AN10: 43 | AO10: 131 | AP10: 0.083685 | AQ10: 0.029943 | AR10: 0.063193 | AS10: 0.116587 | AT10: 21031 | AU10: 1431 | AV10: 0.133978 | AW10: 0.071899 | AX10: 0.173493 | AY10: 0.254081 | AZ10: 0.11644612 | BA10: 0.033095 | BB10: 0.010857 | BC10: 0.066923 | BD10: 0.037681 | BE10: 0.023786 | BF10: 0.085144 | BG10: 0.036903 | BH10: 0.01241 | BI10: 0.045498 | BJ10: 0.022564 | BK10: 0.016104 | BL10: 0.019441 | BM10: 0.308 | BN10: 0.453 | BO10: 0.5502 | BP10: 0.492 | BQ10: 1.8032 | BR10: 0.4325 | BS10: 0.756 | BT10: 0.648 | BU10: 0.645 | BV10: 2.049 | BW10: 0.893 | BX10: 0.103 | BY10: 0.742 | BZ10: 0.845 | CA10: 0.427 | CB10: 0.598 | CC10: 0.687 | CD10: 0.536 | CE10: 0.21 | CF10: 0.702 | CG10: 2.733 | CH10: 0.659 | CI10: 7.4302 | CJ10: 0.6303 | CK10: 0 | CL10: 0 | CM10: 0 | CN10: 0 | CO10: 0 | CP10: 0 | CQ10: 0 | CR10: 0 | CS10: 0 | CT10: 0 | CU10: 0 | CV10: 0 | CW10: 0 | CX10: 0 | CY10: 0 | CZ10: 0 | DA10: 0 | DB10: 0 | DC10: 0 | DD10: (-94.827388098868, 39.959509124107406) | DE10: 0.010752793892895308 | DF10: 0.4952251338642554
A11: 1400000US29003010300 | B11: 29 | C11: 003 | D11: 010300 | E11: 123.71 | F11: 29003 | G11: 29003010300 | H11: MO | I11: Missouri | J11: Andrew County | K11: Census Tract 103, Andrew County, Missouri | L11: 2063 | M11: 1879 | N11: 240 | O11: 940 | P11: 870 | Q11: 73 | R11: 793 | S11: 199 | T11: 82 | U11: 74 | V11: 429 | W11: 19877 | X11: 2791 | Y11: 138 | Z11: 233 | AA11: 249 | AB11: 527 | AC11: 53 | AD11: 63 | AE11: 0 | AF11: 456 | AG11: 0 | AH11: 197 | AI11: 221 | AJ11: 81 | AK11: 31 | AL11: 119 | AM11: 26 | AN11: 116 | AO11: 0 | AP11: 0.105907 | AQ11: 0.04149 | AR11: 0.082681 | AS11: 0.479203 | AT11: 19877 | AU11: 2791 | AV11: 0.107644 | AW11: 0.181429 | AX11: 0.120698 | AY11: 0.255453 | AZ11: 0.0668348 | BA11: 0.030538 | BB11: 0 | BC11: 0.258064 | BD11: 0 | BE11: 0.226436 | BF11: 0.254022 | BG11: 0.09063 | BH11: 0.043971 | BI11: 0.168734 | BJ11: 0.036879 | BK11: 0.164495 | BL11: 0 | BM11: 0.398 | BN11: 0.637 | BO11: 0.6217 | BP11: 0.37 | BQ11: 2.0267 | BR11: 0.5076 | BS11: 0.35 | BT11: 0.656 | BU11: 0.188 | BV11: 1.194 | BW11: 0.225 | BX11: 0.082 | BY11: 0 | BZ11: 0.082 | CA11: 0.039 | CB11: 0 | CC11: 0.953 | CD11: 0.91 | CE11: 0.358 | CF11: 0 | CG11: 2.221 | CH11: 0.425 | CI11: 5.5237 | CJ11: 0.2866 | CK11: 0 | CL11: 0 | CM11: 0 | CN11: 0 | CO11: 0 | CP11: 0 | CQ11: 0 | CR11: 0 | CS11: 0 | CT11: 0 | CU11: 0 | CV11: 0 | CW11: 0 | CX11: 1 | CY11: 1 | CZ11: 0 | DA11: 0 | DB11: 2 | DC11: 2 | DD11: (-94.94694680916884, 40.00133442371098) | DE11: 0.034005082 | DF11: 1.1802298120486299
A12: 1400000US29003010400 | B12: 29 | C12: 003 | D12: 010400 | E12: 203.971 | F12: 29003 | G12: 29003010400 | H12: MO | I12: Missouri | J12: Andrew County | K12: Census Tract 104, Andrew County, Missouri | L12: 3051 | M12: 2663 | N12: 200 | O12: 1342 | P12: 1290 | Q12: 78 | R12: 1184 | S12: 180 | T12: 72 | U12: 65 | V12: 343 | W12: 25416 | X12: 2272 | Y12: 165 | Z12: 284 | AA12: 492 | AB12: 679 | AC12: 69 | AD12: 86 | AE12: 6 | AF12: 442 | AG12: 18 | AH12: 163 | AI12: 164 | AJ12: 44 | AK12: 5 | AL12: 114 | AM12: 54 | AN12: 33 | AO12: 61 | AP12: 0.067873 | AQ12: 0.026677 | AR12: 0.04741 | AS12: 0.250139 | AT12: 25416 | AU12: 2272 | AV12: 0.086796 | AW12: 0.149244 | AX12: 0.161258 | AY12: 0.222549 | AZ12: 0.05827702 | BA12: 0.028187 | BB12: 0.002328 | BC12: 0.171517 | BD12: 0.013953 | BE12: 0.126353 | BF12: 0.127131 | BG12: 0.033231 | BH12: 0.004524 | BI12: 0.103166 | BJ12: 0.048868 | BK12: 0.029567 | BL12: 0.019993 | BM12: 0.238 | BN12: 0.269 | BO12: 0.33 | BP12: 0.28 | BQ12: 1.117 | BR12: 0.231 | BS12: 0.677 | BT12: 0.322 | BU12: 0.122 | BV12: 1.121 | BW12: 0.182 | BX12: 0.068 | BY12: 0.4 | BZ12: 0.468 | CA12: 0.193 | CB12: 0.42 | CC12: 0.771 | CD12: 0.323 | CE12: 0.479 | CF12: 0.712 | CG12: 2.705 | CH12: 0.643 | CI12: 5.411 | CJ12: 0.2664 | CK12: 0 | CL12: 0 | CM12: 0 | CN12: 0 | CO12: 0 | CP12: 0 | CQ12: 0 | CR12: 0 | CS12: 0 | CT12: 0 | CU12: 0 | CV12: 0 | CW12: 0 | CX12: 0 | CY12: 0 | CZ12: 0 | DA12: 0 | DB12: 0 | DC12: 0 | DD12: (-94.72631546660662, 40.01889582775246) | DE12: 0.056214420923513767 | DF12: 1.1812298349320995
A13: 1400000US29005950100 | B13: 29 | C13: 005 | D13: 950100 | E13: 289.679 | F13: 29005 | G13: 29005950100 | H13: MO | I13: Missouri | J13: Atchison County | K13: Census Tract 9501, Atchison County, Missouri | L13: 3215 | M13: 3290 | N13: 174 | O13: 1715 | P13: 1727 | Q13: 83 | R13: 1421 | S13: 450 | T13: 135 | U13: 93 | V13: 305 | W13: 22661 | X13: 2902 | Y13: 299 | Z13: 239 | AA13: 684 | AB13: 653 | AC13: 98 | AD13: 76 | AE13: 11 | AF13: 427 | AG13: 55 | AH13: 47 | AI13: 45 | AJ13: 20 | AK13: 6 | AL13: 114 | AM13: 83 | AN13: 32 | AO13: 43 | AP13: 0.141198 | AQ13: 0.041431 | AR13: 0.0595 | AS13: 0.195084 | AT13: 22661 | AU13: 2902 | AV13: 0.127887 | AW13: 0.101867 | AX13: 0.212752 | AY13: 0.20311 | AZ13: 0.06896551 | BA13: 0.023639 | BB13: 0.003532 | BC13: 0.137122 | BD13: 0.031847 | BE13: 0.027171 | BF13: 0.026056 | BG13: 0.011512 | BH13: 0.004379 | BI13: 0.083211 | BJ13: 0.060583 | BK13: 0.022935 | BL13: 0.013374 | BM13: 0.551 | BN13: 0.411 | BO13: 0.4628 | BP13: 0.461 | BQ13: 1.8858 | BR13: 0.4585 | BS13: 0.915 | BT13: 0.2 | BU13: 0.206 | BV13: 1.321 | BW13: 0.319 | BX13: 0.035 | BY13: 0.484 | BZ13: 0.519 | CA13: 0.218 | CB13: 0.558 | CC13: 0.535 | CD13: 0.317 | CE13: 0.571 | CF13: 0.625 | CG13: 2.606 | CH13: 0.607 | CI13: 6.3318 | CJ13: 0.4347 | CK13: 0 | CL13: 0 | CM13: 0 | CN13: 0 | CO13: 0 | CP13: 1 | CQ13: 0 | CR13: 0 | CS13: 1 | CT13: 0 | CU13: 0 | CV13: 0 | CW13: 0 | CX13: 0 | CY13: 0 | CZ13: 0 | DA13: 0 | DB13: 0 | DC13: 1 | DD13: (-95.31156076943688, 40.417536536694634) | DE13: 0.079628197 | DF13: 1.2342055307466386
A14: 1400000US29005950200 | B14: 29 | C14: 005 | D14: 950200 | E14: 257.623 | F14: 29005 | G14: 29005950200 | H14: MO | I14: Missouri | J14: Atchison County | K14: Census Tract 9502, Atchison County, Missouri | L14: 2470 | M14: 2521 | N14: 174 | O14: 1270 | P14: 1288 | Q14: 58 | R14: 1077 | S14: 299 | T14: 124 | U14: 41 | V14: 395 | W14: 24962 | X14: 2759 | Y14: 289 | Z14: 244 | AA14: 543 | AB14: 529 | AC14: 85 | AD14: 53 | AE14: 0 | AF14: 456 | AG14: 16 | AH14: 115 | AI14: 59 | AJ14: 25 | AK14: 2 | AL14: 114 | AM14: 63 | AN14: 27 | AO14: 55 | AP14: 0.118603 | AQ14: 0.0485 | AR14: 0.035528 | AS14: 0.342238 | AT14: 24962 | AU14: 2759 | AV14: 0.157321 | AW14: 0.132116 | AX14: 0.219838 | AY14: 0.21417 | AZ14: 0.07892293 | BA14: 0.021457 | BB14: 0 | BC14: 0.193548 | BD14: 0.012422 | BE14: 0.089283 | BF14: 0.045807 | BG14: 0.0193 | BH14: 0.001811 | BI14: 0.10326 | BJ14: 0.057065 | BK14: 0.024049 | BL14: 0.022267 | BM14: 0.449 | BN14: 0.141 | BO14: 0.3509 | BP14: 0.598 | BQ14: 1.5389 | BR14: 0.3538 | BS14: 0.932 | BT14: 0.259 | BU14: 0.293 | BV14: 1.484 | BW14: 0.471 | BX14: 0.023 | BY14: 0 | BZ14: 0.023 | CA14: 0.012 | CB14: 0.405 | CC14: 0.594 | CD14: 0.28 | CE14: 0.547 | CF14: 0.74 | CG14: 2.566 | CH14: 0.59 | CI14: 5.6119 | CJ14: 0.3054 | CK14: 0 | CL14: 0 | CM14: 0 | CN14: 0 | CO14: 0 | CP14: 1 | CQ14: 0 | CR14: 0 | CS14: 1 | CT14: 0 | CU14: 0 | CV14: 0 | CW14: 0 | CX14: 0 | CY14: 0 | CZ14: 0 | DA14: 0 | DB14: 0 | DC14: 1 | DD14: (-95.55775070299288, 40.44561069852723) | DE14: 0.07157146 | DF14: 1.5045638651498037
A15: 1400000US29007950100 | B15: 29 | C15: 007 | D15: 950100 | E15: 12.577 | F15: 29007 | G15: 29007950100 | H15: MO | I15: Missouri | J15: Audrain County | K15: Census Tract 9501, Audrain County, Missouri | L15: 4180 | M15: 4206 | N15: 236 | O15: 1391 | P15: 1202 | Q15: 177 | R15: 1185 | S15: 524 | T15: 297 | U15: 75 | V15: 447 | W15: 10017 | X15: 1342 | Y15: 859 | Z15: 293 | AA15: 596 | AB15: 633 | AC15: 167 | AD15: 787 | AE15: 22 | AF15: 412 | AG15: 6 | AH15: 162 | AI15: 43 | AJ15: 55 | AK15: 27 | AL15: 119 | AM15: 132 | AN15: 84 | AO15: 1505 | AP15: 0.232578 | AQ15: 0.12751 | AR15: 0.077081 | AS15: 0.459119 | AT15: 10017 | AU15: 1342 | AV15: 0.259516 | AW15: 0.086462 | AX15: 0.142583 | AY15: 0.151435 | AZ15: 0.14092827 | BA15: 0.188277 | BB15: 0.005412 | BC15: 0.101352 | BD15: 0.004991 | BE15: 0.134773 | BF15: 0.035773 | BG15: 0.045452 | BH15: 0.027054 | BI15: 0.119165 | BJ15: 0.132264 | BK15: 0.081656 | BL15: 0.360047 | BM15: 0.796 | BN15: 0.581 | BO15: 0.9884 | BP15: 0.889 | BQ15: 3.2544 | BR15: 0.8686 | BS15: 0.523 | BT15: 0.071 | BU15: 0.762 | BV15: 1.356 | BW15: 0.352 | BX15: 0.692 | BY15: 0.576 | BZ15: 1.268 | CA15: 0.694 | CB15: 0.316 | CC15: 0.566 | CD15: 0.78 | CE15: 0.834 | CF15: 0.986 | CG15: 3.482 | CH15: 0.93 | CI15: 9.3604 | CJ15: 0.8953 | CK15: 0 | CL15: 0 | CM15: 1 | CN15: 0 | CO15: 1 | CP15: 0 | CQ15: 0 | CR15: 0 | CS15: 0 | CT15: 0 | CU15: 0 | CV15: 0 | CW15: 0 | CX15: 0 | CY15: 0 | CZ15: 0 | DA15: 1 | DB15: 1 | DC15: 2 | DD15: (-91.49406358552488, 39.30599546517992) | DE15: 0.0034116709 | DF15: 0.2919619598352852
A16: 1400000US29007950600 | B16: 29 | C16: 007 | D16: 950600 | E16: 6.557 | F16: 29007 | G16: 29007950600 | H16: MO | I16: Missouri | J16: Audrain County | K16: Census Tract 9506, Audrain County, Missouri | L16: 2899 | M16: 2935 | N16: 331 | O16: 1356 | P16: 1400 | Q16: 90 | R16: 1215 | S16: 373 | T16: 247 | U16: 50 | V16: 458 | W16: 21236 | X16: 2391 | Y16: 287 | Z16: 337 | AA16: 504 | AB16: 750 | AC16: 205 | AD16: 367 | AE16: 0 | AF16: 456 | AG16: 10 | AH16: 162 | AI16: 93 | AJ16: 75 | AK16: 0 | AL16: 161 | AM16: 87 | AN16: 57 | AO16: 29 | AP16: 0.127086 | AQ16: 0.082927 | AR16: 0.037878 | AS16: 0.346913 | AT16: 21236 | AU16: 2391 | AV16: 0.150261 | AW16: 0.176001 | AX16: 0.173853 | AY16: 0.258709 | AZ16: 0.16872427 | BA16: 0.126595 | BB16: 0 | BC16: 0.172792 | BD16: 0.007142 | BE16: 0.115713 | BF16: 0.066428 | BG16: 0.0534 | BH16: 0 | BI16: 0.131321 | BJ16: 0.070962 | BK16: 0.046046 | BL16: 0.010003 | BM16: 0.485 | BN16: 0.161 | BO16: 0.5379 | BP16: 0.568 | BQ16: 1.7519 | BR16: 0.4159 | BS16: 0.757 | BT16: 0.693 | BU16: 0.843 | BV16: 2.293 | BW16: 0.979 | BX16: 0.551 | BY16: 0 | BZ16: 0.551 | CA16: 0.241 | CB16: 0.353 | CC16: 0.641 | CD16: 0 | CE16: 0.63 | CF16: 0.58 | CG16: 2.204 | CH16: 0.42 | CI16: 6.7999 | CJ16: 0.5119 | CK16: 0 | CL16: 0 | CM16: 0 | CN16: 0 | CO16: 0 | CP16: 0 | CQ16: 0 | CR16: 0 | CS16: 0 | CT16: 0 | CU16: 0 | CV16: 0 | CW16: 0 | CX16: 0 | CY16: 0 | CZ16: 0 | DA16: 0 | DB16: 0 | DC16: 0 | DD16: (-91.92280961014657, 39.158831454125405) | DE16: 0.0017786718 | DF16: 0.2646855368188617
A17: 1400000US29007950200 | B17: 29 | C17: 007 | D17: 950200 | E17: 404.809 | F17: 29007 | G17: 29007950200 | H17: MO | I17: Missouri | J17: Audrain County | K17: Census Tract 9502, Audrain County, Missouri | L17: 4917 | M17: 5083 | N17: 435 | O17: 2318 | P17: 2273 | Q17: 154 | R17: 2019 | S17: 352 | T17: 127 | U17: 116 | V17: 329 | W17: 23750 | X17: 2794 | Y17: 613 | Z17: 208 | AA17: 894 | AB17: 1129 | AC17: 183 | AD17: 99 | AE17: 44 | AF17: 428 | AG17: 2 | AH17: 161 | AI17: 361 | AJ17: 108 | AK17: 12 | AL17: 115 | AM17: 37 | AN17: 23 | AO17: 0 | AP17: 0.069441 | AQ17: 0.024345 | AR17: 0.047231 | AS17: 0.133878 | AT17: 23750 | AU17: 2794 | AV17: 0.166576 | AW17: 0.054943 | AX17: 0.181818 | AY17: 0.229611 | AZ17: 0.09063893 | BA17: 0.020134 | BB17: 0.008979 | BC17: 0.087343 | BD17: 0.000879 | BE17: 0.070831 | BF17: 0.15882 | BG17: 0.046279 | BH17: 0.005879 | BI17: 0.056342 | BJ17: 0.018128 | BK17: 0.011173 | BL17: 0 | BM17: 0.248 | BN17: 0.266 | BO17: 0.4079 | BP17: 0.641 | BQ17: 1.5629 | BR17: 0.361 | BS17: 0.802 | BT17: 0.38 | BU17: 0.409 | BV17: 1.591 | BW17: 0.563 | BX17: 0.02 | BY17: 0.695 | BZ17: 0.715 | CA17: 0.346 | CB17: 0.253 | CC17: 0.836 | CD17: 0.353 | CE17: 0.165 | CF17: 0 | CG17: 1.607 | CH17: 0.201 | CI17: 5.4759 | CJ17: 0.2758 | CK17: 0 | CL17: 0 | CM17: 0 | CN17: 0 | CO17: 0 | CP17: 0 | CQ17: 0 | CR17: 0 | CS17: 0 | CT17: 0 | CU17: 0 | CV17: 0 | CW17: 0 | CX17: 0 | CY17: 0 | CZ17: 0 | DA17: 0 | DB17: 0 | DC17: 0 | DD17: (-91.70641956419668, 39.21111885256495) | DE17: 0.10999824699578266 | DF17: 2.1213853714958257
A18: 1400000US29007950300 | B18: 29 | C18: 007 | D18: 950300 | E18: 236.042 | F18: 29007 | G18: 29007950300 | H18: MO | I18: Missouri | J18: Audrain County | K18: Census Tract 9503, Audrain County, Missouri | L18: 3609 | M18: 3917 | N18: 453 | O18: 1256 | P18: 1343 | Q18: 121 | R18: 1148 | S18: 994 | T18: 520 | U18: 59 | V18: 444 | W18: 18894 | X18: 3389 | Y18: 384 | Z18: 335 | AA18: 413 | AB18: 1231 | AC18: 56 | AD18: 95 | AE18: 18 | AF18: 442 | AG18: 8 | AH18: 162 | AI18: 136 | AJ18: 66 | AK18: 22 | AL18: 29 | AM18: 122 | AN18: 88 | AO18: 58 | AP18: 0.253765 | AQ18: 0.12947 | AR18: 0.033484 | AS18: 0.251919 | AT18: 18894 | AU18: 3389 | AV18: 0.168273 | AW18: 0.14602 | AX18: 0.114436 | AY18: 0.341091 | AZ18: 0.04878048 | BA18: 0.026323 | BB18: 0.005116 | BC18: 0.125638 | BD18: 0.005956 | BE18: 0.120624 | BF18: 0.101265 | BG18: 0.048289 | BH18: 0.017336 | BI18: 0.02279 | BJ18: 0.096138 | BK18: 0.068717 | BL18: 0.01607 | BM18: 0.832 | BN18: 0.117 | BO18: 0.678 | BP18: 0.649 | BQ18: 2.276 | BR18: 0.5935 | BS18: 0.307 | BT18: 0.981 | BU18: 0.065 | BV18: 1.353 | BW18: 0.347 | BX18: 0.053 | BY18: 0.568 | BZ18: 0.621 | CA18: 0.286 | CB18: 0.336 | CC18: 0.718 | CD18: 0.634 | CE18: 0.741 | CF18: 0.661 | CG18: 3.09 | CH18: 0.814 | CI18: 7.34 | CJ18: 0.6166 | CK18: 0 | CL18: 0 | CM18: 0 | CN18: 0 | CO18: 0 | CP18: 0 | CQ18: 1 | CR18: 0 | CS18: 1 | CT18: 0 | CU18: 0 | CV18: 0 | CW18: 0 | CX18: 0 | CY18: 0 | CZ18: 0 | DA18: 0 | DB18: 0 | DC18: 1 | DD18: (-92.08599050663638, 39.2265404727495) | DE18: 0.064089361 | DF18: 1.4717639669620064
A19: 1400000US29007950400 | B19: 29 | C19: 007 | D19: 950400 | E19: 12.425 | F19: 29007 | G19: 29007950400 | H19: MO | I19: Missouri | J19: Audrain County | K19: Census Tract 9504, Audrain County, Missouri | L19: 2942 | M19: 2703 | N19: 371 | O19: 1229 | P19: 1272 | Q19: 103 | R19: 1095 | S19: 355 | T19: 173 | U19: 77 | V19: 414 | W19: 19023 | X19: 2646 | Y19: 263 | Z19: 317 | AA19: 401 | AB19: 866 | AC19: 149 | AD19: 561 | AE19: 0 | AF19: 456 | AG19: 43 | AH19: 174 | AI19: 0 | AJ19: 114 | AK19: 0 | AL19: 161 | AM19: 37 | AN19: 30 | AO19: 353 | AP19: 0.14104 | AQ19: 0.065618 | AR19: 0.074468 | AS19: 0.400049 | AT19: 19023 | AU19: 2646 | AV19: 0.148839 | AW19: 0.178129 | AX19: 0.136301 | AY19: 0.294357 | AZ19: 0.13607305 | BA19: 0.190686 | BB19: 0 | BC19: 0.183353 | BD19: 0.033805 | BE19: 0.136765 | BF19: 0 | BG19: 0.089622 | BH19: 0 | BI19: 0.147031 | BJ19: 0.033789 | BK19: 0.027088 | BL19: 0.119986 | BM19: 0.549 | BN19: 0.551 | BO19: 0.6693 | BP19: 0.562 | BQ19: 2.3313 | BR19: 0.6087 | BS19: 0.466 | BT19: 0.901 | BU19: 0.744 | BV19: 2.111 | BW19: 0.922 | BX19: 0.696 | BY19: 0 | BZ19: 0.696 | CA19: 0.333 | CB19: 0.57 | CC19: 0 | CD19: 0 | CE19: 0.324 | CF19: 0.948 | CG19: 1.842 | CH19: 0.282 | CI19: 6.9803 | CJ19: 0.5415 | CK19: 0 | CL19: 0 | CM19: 0 | CN19: 0 | CO19: 0 | CP19: 0 | CQ19: 1 | CR19: 0 | CS19: 1 | CT19: 0 | CU19: 0 | CV19: 0 | CW19: 0 | CX19: 0 | CY19: 0 | CZ19: 0 | DA19: 1 | DB19: 1 | DC19: 2 | DD19: (-91.84497172049963, 39.18015155190388) | DE19: 0.0034625486 | DF19: 0.3088923060010687
A20: 1400000US29007950500 | B20: 29 | C20: 007 | D20: 950500 | E20: 8.603 | F20: 29007 | G20: 29007950500 | H20: MO | I20: Missouri | J20: Audrain County | K20: Census Tract 9505, Audrain County, Missouri | L20: 3582 | M20: 3153 | N20: 282 | O20: 1602 | P20: 1627 | Q20: 110 | R20: 1450 | S20: 537 | T20: 325 | U20: 21 | V20: 471 | W20: 21741 | X20: 3472 | Y20: 390 | Z20: 267 | AA20: 688 | AB20: 889 | AC20: 192 | AD20: 392 | AE20: 37 | AF20: 443 | AG20: 35 | AH20: 168 | AI20: 116 | AJ20: 78 | AK20: 0 | AL20: 161 | AM20: 130 | AN20: 86 | AO20: 84 | AP20: 0.171182 | AQ20: 0.102477 | AR20: 0.013833 | AS20: 0.310266 | AT20: 21741 | AU20: 3472 | AV20: 0.17687 | AW20: 0.120042 | AX20: 0.192071 | AY20: 0.248185 | AZ20: 0.13241379 | BA20: 0.109436 | BB20: 0.012239 | BC20: 0.146539 | BD20: 0.021511 | BE20: 0.103247 | BF20: 0.071296 | BG20: 0.047698 | BH20: 0 | BI20: 0.118035 | BJ20: 0.095307 | BK20: 0.062371 | BL20: 0.02345 | BM20: 0.648 | BN20: 0.014 | BO20: 0.5097 | BP20: 0.676 | BQ20: 1.8477 | BR20: 0.4462 | BS20: 0.848 | BT20: 0.576 | BU20: 0.727 | BV20: 2.151 | BW20: 0.948 | BX20: 0.502 | BY20: 0.775 | BZ20: 1.277 | CA20: 0.7 | CB20: 0.481 | CC20: 0.653 | CD20: 0 | CE20: 0.738 | CF20: 0.75 | CG20: 2.622 | CH20: 0.61 | CI20: 7.8977 | CJ20: 0.6975 | CK20: 0 | CL20: 0 | CM20: 0 | CN20: 0 | CO20: 0 | CP20: 0 | CQ20: 0 | CR20: 0 | CS20: 0 | CT20: 0 | CU20: 0 | CV20: 0 | CW20: 0 | CX20: 0 | CY20: 0 | CZ20: 0 | DA20: 0 | DB20: 0 | DC20: 0 | DD20: (-91.90685506051464, 39.19941590422084) | DE20: 0.0023539734 | DF20: 0.2342357670113388
A21: 1400000US29007950700 | B21: 29 | C21: 007 | D21: 950700 | E21: 11.222 | F21: 29007 | G21: 29007950700 | H21: MO | I21: Missouri | J21: Audrain County | K21: Census Tract 9507, Audrain County, Missouri | L21: 3400 | M21: 3687 | N21: 400 | O21: 1700 | P21: 1790 | Q21: 104 | R21: 1478 | S21: 850 | T21: 312 | U21: 84 | V21: 444 | W21: 17277 | X21: 2489 | Y21: 465 | Z21: 335 | AA21: 588 | AB21: 871 | AC21: 226 | AD21: 615 | AE21: 106 | AF21: 423 | AG21: 89 | AH21: 124 | AI21: 113 | AJ21: 69 | AK21: 42 | AL21: 124 | AM21: 226 | AN21: 114 | AO21: 71 | AP21: 0.233644 | AQ21: 0.082215 | AR21: 0.055263 | AS21: 0.291995 | AT21: 17277 | AU21: 2489 | AV21: 0.216379 | AW21: 0.153954 | AX21: 0.172941 | AY21: 0.256176 | AZ21: 0.15290933 | BA21: 0.180882 | BB21: 0.032111 | BC21: 0.128099 | BD21: 0.04972 | BE21: 0.069213 | BF21: 0.063128 | BG21: 0.038372 | BH21: 0.02729 | BI21: 0.080537 | BJ21: 0.146848 | BK21: 0.072978 | BL21: 0.020882 | BM21: 0.799 | BN21: 0.348 | BO21: 0.7668 | BP21: 0.794 | BQ21: 2.7078 | BR21: 0.7242 | BS21: 0.753 | BT21: 0.664 | BU21: 0.803 | BV21: 2.22 | BW21: 0.967 | BX21: 0.681 | BY21: 0.923 | BZ21: 1.604 | CA21: 0.874 | CB21: 0.656 | CC21: 0.633 | CD21: 0.783 | CE21: 0.853 | CF21: 0.719 | CG21: 3.644 | CH21: 0.967 | CI21: 10.1758 | CJ21: 0.9596 | CK21: 0 | CL21: 0 | CM21: 0 | CN21: 0 | CO21: 0 | CP21: 0 | CQ21: 0 | CR21: 0 | CS21: 0 | CT21: 0 | CU21: 1 | CV21: 1 | CW21: 0 | CX21: 0 | CY21: 0 | CZ21: 0 | DA21: 0 | DB21: 0 | DC21: 1 | DD21: (-91.866893695359, 39.14326336148947) | DE21: 0.0031322476 | DF21: 0.37377872615950997
A22: 1400000US29009960300 | B22: 29 | C22: 009 | D22: 960300 | E22: 15.023 | F22: 29009 | G22: 29009960300 | H22: MO | I22: Missouri | J22: Barry County | K22: Census Tract 9603, Barry County, Missouri | L22: 6400 | M22: 6601 | N22: 354 | O22: 2778 | P22: 2736 | Q22: 266 | R22: 2444 | S22: 1566 | T22: 616 | U22: 193 | V22: 473 | W22: 21940 | X22: 4115 | Y22: 927 | Z22: 293 | AA22: 909 | AB22: 1782 | AC22: 344 | AD22: 1539 | AE22: 288 | AF22: 439 | AG22: 158 | AH22: 165 | AI22: 153 | AJ22: 109 | AK22: 105 | AL22: 137 | AM22: 130 | AN22: 80 | AO22: 132 | AP22: 0.249243 | AQ22: 0.09665 | AR22: 0.065534 | AS22: 0.160394 | AT22: 21940 | AU22: 4115 | AV22: 0.216386 | AW22: 0.065645 | AX22: 0.142031 | AY22: 0.278437 | AZ22: 0.14075286 | BA22: 0.240468 | BB22: 0.048024 | BC22: 0.073131 | BD22: 0.057748 | BE22: 0.060045 | BF22: 0.055921 | BG22: 0.039466 | BH22: 0.040887 | BI22: 0.05317 | BJ22: 0.050623 | BK22: 0.03068 | BL22: 0.020625 | BM22: 0.826 | BN22: 0.474 | BO22: 0.4968 | BP22: 0.794 | BQ22: 2.5908 | BR22: 0.6989 | BS22: 0.516 | BT22: 0.841 | BU22: 0.761 | BV22: 2.118 | BW22: 0.927 | BX22: 0.753 | BY22: 0.957 | BZ22: 1.71 | CA22: 0.928 | CB22: 0.68 | CC22: 0.621 | CD22: 0.896 | CE22: 0.49 | CF22: 0.717 | CG22: 3.404 | CH22: 0.917 | CI22: 9.8228 | CJ22: 0.9372 | CK22: 0 | CL22: 0 | CM22: 0 | CN22: 0 | CO22: 0 | CP22: 0 | CQ22: 0 | CR22: 0 | CS22: 0 | CT22: 0 | CU22: 1 | CV22: 1 | CW22: 0 | CX22: 0 | CY22: 0 | CZ22: 0 | DA22: 0 | DB22: 0 | DC22: 1 | DD22: (-93.93529499098366, 36.90135049133804) | DE22: 0.0039407882 | DF22: 0.26165885194892247
A23: 1400000US29009960402 | B23: 29 | C23: 009 | D23: 960402 | E23: 78.446 | F23: 29009 | G23: 29009960402 | H23: MO | I23: Missouri | J23: Barry County | K23: Census Tract 9604.02, Barry County, Missouri | L23: 3641 | M23: 3266 | N23: 377 | O23: 1540 | P23: 1551 | Q23: 128 | R23: 1330 | S23: 520 | T23: 214 | U23: 129 | V23: 347 | W23: 16973 | X23: 2425 | Y23: 572 | Z23: 137 | AA23: 487 | AB23: 1064 | AC23: 143 | AD23: 526 | AE23: 75 | AF23: 399 | AG23: 0 | AH23: 197 | AI23: 365 | AJ23: 103 | AK23: 30 | AL23: 117 | AM23: 70 | AN23: 37 | AO23: 0 | AP23: 0.16124 | AQ23: 0.063711 | AR23: 0.082586 | AS23: 0.221878 | AT23: 16973 | AU23: 2425 | AV23: 0.264447 | AW23: 0.056384 | AX23: 0.133754 | AY23: 0.292227 | AZ23: 0.10751879 | BA23: 0.144465 | BB23: 0.02439 | BC23: 0.129726 | BD23: 0 | BE23: 0.127014 | BF23: 0.235332 | BG23: 0.063505 | BH23: 0.023076 | BI23: 0.089965 | BJ23: 0.053846 | BK23: 0.027864 | BL23: 0 | BM23: 0.615 | BN23: 0.636 | BO23: 0.7877 | BP23: 0.896 | BQ23: 2.9347 | BR23: 0.7913 | BS23: 0.448 | BT23: 0.894 | BU23: 0.564 | BV23: 1.906 | BW23: 0.805 | BX23: 0.602 | BY23: 0.886 | BZ23: 1.488 | CA23: 0.817 | CB23: 0 | CC23: 0.937 | CD23: 0.728 | CE23: 0.519 | CF23: 0 | CG23: 2.184 | CH23: 0.412 | CI23: 8.5127 | CJ23: 0.7892 | CK23: 0 | CL23: 0 | CM23: 0 | CN23: 0 | CO23: 0 | CP23: 0 | CQ23: 0 | CR23: 0 | CS23: 0 | CT23: 0 | CU23: 0 | CV23: 0 | CW23: 0 | CX23: 1 | CY23: 0 | CZ23: 0 | DA23: 0 | DB23: 1 | DC23: 1 | DD23: (-93.97964257866084, 36.69361701569102) | DE23: 0.020518241651175002 | DF23: 0.7289054187874155
A24: 1400000US29009960500 | B24: 29 | C24: 009 | D24: 960500 | E24: 67.413 | F24: 29009 | G24: 29009960500 | H24: MO | I24: Missouri | J24: Barry County | K24: Census Tract 9605, Barry County, Missouri | L24: 6054 | M24: 5727 | N24: 552 | O24: 2626 | P24: 2588 | Q24: 191 | R24: 2377 | S24: 698 | T24: 271 | U24: 159 | V24: 438 | W24: 20198 | X24: 2553 | Y24: 424 | Z24: 297 | AA24: 1121 | AB24: 1445 | AC24: 246 | AD24: 375 | AE24: 49 | AF24: 429 | AG24: 96 | AH24: 135 | AI24: 492 | AJ24: 169 | AK24: 73 | AL24: 131 | AM24: 138 | AN24: 81 | AO24: 164 | AP24: 0.123343 | AQ24: 0.04634 | AR24: 0.059572 | AS24: 0.163854 | AT24: 20198 | AU24: 2553 | AV24: 0.112946 | AW24: 0.078222 | AX24: 0.185166 | AY24: 0.238685 | AZ24: 0.10349179 | BA24: 0.061942 | BB24: 0.009082 | BC24: 0.079513 | BD24: 0.037094 | BE24: 0.052091 | BF24: 0.190108 | BG24: 0.063776 | BH24: 0.030366 | BI24: 0.054422 | BJ24: 0.057404 | BK24: 0.033285 | BL24: 0.027089 | BM24: 0.466 | BN24: 0.413 | BO24: 0.6007 | BP24: 0.392 | BQ24: 1.8717 | BR24: 0.4542 | BS24: 0.817 | BT24: 0.482 | BU24: 0.527 | BV24: 1.826 | BW24: 0.746 | BX24: 0.323 | BY24: 0.699 | BZ24: 1.022 | CA24: 0.57 | CB24: 0.595 | CC24: 0.882 | CD24: 0.814 | CE24: 0.551 | CF24: 0.787 | CG24: 3.629 | CH24: 0.964 | CI24: 8.3487 | CJ24: 0.7668 | CK24: 0 | CL24: 0 | CM24: 0 | CN24: 0 | CO24: 0 | CP24: 0 | CQ24: 0 | CR24: 0 | CS24: 0 | CT24: 0 | CU24: 0 | CV24: 0 | CW24: 0 | CX24: 0 | CY24: 0 | CZ24: 0 | DA24: 0 | DB24: 0 | DC24: 0 | DD24: (-93.84755158809095, 36.651867407983744) | DE24: 0.017614711838179226 | DF24: 0.72672309
A25: 1400000US29009960600 | B25: 29 | C25: 009 | D25: 960600 | E25: 35.897 | F25: 29009 | G25: 29009960600 | H25: MO | I25: Missouri | J25: Barry County | K25: Census Tract 9606, Barry County, Missouri | L25: 2767 | M25: 3134 | N25: 519 | O25: 2352 | P25: 2276 | Q25: 89 | R25: 1344 | S25: 433 | T25: 231 | U25: 145 | V25: 386 | W25: 21932 | X25: 3274 | Y25: 404 | Z25: 241 | AA25: 1005 | AB25: 293 | AC25: 54 | AD25: 85 | AE25: 51 | AF25: 448 | AG25: 0 | AH25: 197 | AI25: 473 | AJ25: 130 | AK25: 27 | AL25: 116 | AM25: 18 | AN25: 17 | AO25: 0 | AP25: 0.13825 | AQ25: 0.070106 | AR25: 0.133272 | AS25: 0.352634 | AT25: 21932 | AU25: 3274 | AV25: 0.158617 | AW25: 0.092221 | AX25: 0.363209 | AY25: 0.10589 | AZ25: 0.04017857 | BA25: 0.030719 | BB25: 0.016612 | BC25: 0.145904 | BD25: 0 | BE25: 0.086555 | BF25: 0.20782 | BG25: 0.056536 | BH25: 0.019536 | BI25: 0.083901 | BJ25: 0.013024 | BK25: 0.012194 | BL25: 0 | BM25: 0.535 | BN25: 0.865 | BO25: 0.4982 | BP25: 0.605 | BQ25: 2.5032 | BR25: 0.6664 | BS25: 0.997 | BT25: 0.027 | BU25: 0.038 | BV25: 1.062 | BW25: 0.143 | BX25: 0.084 | BY25: 0.834 | BZ25: 0.918 | CA25: 0.481 | CB25: 0 | CC25: 0.908 | CD25: 0.676 | CE25: 0.114 | CF25: 0 | CG25: 1.698 | CH25: 0.233 | CI25: 6.1812 | CJ25: 0.4022 | CK25: 0 | CL25: 0 | CM25: 0 | CN25: 0 | CO25: 0 | CP25: 1 | CQ25: 0 | CR25: 0 | CS25: 1 | CT25: 0 | CU25: 0 | CV25: 0 | CW25: 0 | CX25: 1 | CY25: 0 | CZ25: 0 | DA25: 0 | DB25: 1 | DC25: 2 | DD25: (-93.6464339859266, 36.53982965721335) | DE25: 0.011183342 | DF25: 0.6237392039146049
A26: 1400000US29009960100 | B26: 29 | C26: 009 | D26: 960100 | E26: 277.076 | F26: 29009 | G26: 29009960100 | H26: MO | I26: Missouri | J26: Barry County | K26: Census Tract 9601, Barry County, Missouri | L26: 6127 | M26: 6163 | N26: 563 | O26: 3551 | P26: 3382 | Q26: 155 | R26: 2556 | S26: 639 | T26: 235 | U26: 239 | V26: 401 | W26: 19899 | X26: 2570 | Y26: 803 | Z26: 292 | AA26: 1259 | AB26: 1220 | AC26: 177 | AD26: 289 | AE26: 0 | AF26: 456 | AG26: 0 | AH26: 197 | AI26: 661 | AJ26: 173 | AK26: 63 | AL26: 127 | AM26: 39 | AN26: 34 | AO26: 0 | AP26: 0.105029 | AQ26: 0.037501 | AR26: 0.098273 | AS26: 0.164334 | AT26: 19899 | AU26: 2570 | AV26: 0.183584 | AW26: 0.064793 | AX26: 0.205483 | AY26: 0.199118 | AZ26: 0.06924882 | BA26: 0.047168 | BB26: 0 | BC26: 0.078458 | BD26: 0 | BE26: 0.058249 | BF26: 0.195446 | BG26: 0.050362 | BH26: 0.024174 | BI26: 0.048692 | BJ26: 0.014965 | BK26: 0.012988 | BL26: 0 | BM26: 0.39 | BN26: 0.722 | BO26: 0.6209 | BP26: 0.697 | BQ26: 2.4299 | BR26: 0.6419 | BS26: 0.897 | BT26: 0.184 | BU26: 0.209 | BV26: 1.29 | BW26: 0.294 | BX26: 0.23 | BY26: 0 | BZ26: 0.23 | CA26: 0.101 | CB26: 0 | CC26: 0.892 | CD26: 0.745 | CE26: 0.133 | CF26: 0 | CG26: 1.77 | CH26: 0.258 | CI26: 5.7199 | CJ26: 0.3242 | CK26: 0 | CL26: 0 | CM26: 0 | CN26: 0 | CO26: 0 | CP26: 0 | CQ26: 0 | CR26: 0 | CS26: 0 | CT26: 0 | CU26: 0 | CV26: 0 | CW26: 0 | CX26: 0 | CY26: 0 | CZ26: 0 | DA26: 0 | DB26: 0 | DC26: 0 | DD26: (-93.69522661774658, 36.74448992556688) | DE26: 0.073554385 | DF26: 1.5223946765426895
A27: 1400000US29009960200 | B27: 29 | C27: 009 | D27: 960200 | E27: 173.85 | F27: 29009 | G27: 29009960200 | H27: MO | I27: Missouri | J27: Barry County | K27: Census Tract 9602, Barry County, Missouri | L27: 6418 | M27: 7123 | N27: 627 | O27: 2752 | P27: 2907 | Q27: 150 | R27: 2389 | S27: 1316 | T27: 386 | U27: 360 | V27: 304 | W27: 17093 | X27: 2275 | Y27: 1157 | Z27: 254 | AA27: 875 | AB27: 1787 | AC27: 268 | AD27: 1034 | AE27: 265 | AF27: 416 | AG27: 22 | AH27: 115 | AI27: 559 | AJ27: 146 | AK27: 105 | AL27: 136 | AM27: 52 | AN27: 28 | AO27: 0 | AP27: 0.185039 | AQ27: 0.051773 | AR27: 0.112079 | AS27: 0.093812 | AT27: 17093 | AU27: 2275 | AV27: 0.257626 | AW27: 0.051845 | AX27: 0.136335 | AY27: 0.278435 | AZ27: 0.11218082 | BA27: 0.161109 | BB27: 0.040012 | BC27: 0.062716 | BD27: 0.007567 | BE27: 0.039557 | BF27: 0.192294 | BG27: 0.049233 | BH27: 0.04165 | BI27: 0.053852 | BJ27: 0.020626 | BK27: 0.010993 | BL27: 0 | BM27: 0.688 | BN27: 0.793 | BO27: 0.7805 | BP27: 0.886 | BQ27: 3.1475 | BR27: 0.839 | BS27: 0.466 | BT27: 0.841 | BU27: 0.605 | BV27: 1.912 | BW27: 0.807 | BX27: 0.653 | BY27: 0.947 | BZ27: 1.6 | CA27: 0.871 | CB27: 0.359 | CC27: 0.886 | CD27: 0.9 | CE27: 0.189 | CF27: 0 | CG27: 2.334 | CH27: 0.473 | CI27: 8.9935 | CJ27: 0.852 | CK27: 0 | CL27: 0 | CM27: 0 | CN27: 0 | CO27: 0 | CP27: 0 | CQ27: 0 | CR27: 0 | CS27: 0 | CT27: 0 | CU27: 1 | CV27: 1 | CW27: 0 | CX27: 0 | CY27: 1 | CZ27: 0 | DA27: 0 | DB27: 1 | DC27: 2 | DD27: (-93.92602773996794, 36.82529288837706) | DE27: 0.045559149526850945 | DF27: 1.313433048625097
A28: 1400000US29009960401 | B28: 29 | C28: 009 | D28: 960401 | E28: 130.545 | F28: 29009 | G28: 29009960401 | H28: MO | I28: Missouri | J28: Barry County | K28: Census Tract 9604.01, Barry County, Missouri | L28: 4190 | M28: 3739 | N28: 394 | O28: 1924 | P28: 1941 | Q28: 106 | R28: 1617 | S28: 859 | T28: 338 | U28: 139 | V28: 371 | W28: 16905 | X28: 3480 | Y28: 577 | Z28: 297 | AA28: 615 | AB28: 1049 | AC28: 166 | AD28: 244 | AE28: 0 | AF28: 456 | AG28: 0 | AH28: 197 | AI28: 643 | AJ28: 143 | AK28: 49 | AL28: 118 | AM28: 78 | AN28: 63 | AO28: 0 | AP28: 0.230913 | AQ28: 0.087558 | AR28: 0.077093 | AS28: 0.205455 | AT28: 16905 | AU28: 3480 | AV28: 0.243665 | AW28: 0.122646 | AX28: 0.146778 | AY28: 0.250358 | AZ28: 0.10265924 | BA28: 0.058233 | BB28: 0 | BC28: 0.135835 | BD28: 0 | BE28: 0.101494 | BF28: 0.331272 | BG28: 0.071417 | BH28: 0.03322 | BI28: 0.079934 | BJ28: 0.052881 | BK28: 0.042398 | BL28: 0 | BM28: 0.792 | BN28: 0.582 | BO28: 0.7928 | BP28: 0.857 | BQ28: 3.0238 | BR28: 0.8072 | BS28: 0.552 | BT28: 0.6 | BU28: 0.516 | BV28: 1.668 | BW28: 0.614 | BX28: 0.303 | BY28: 0 | BZ28: 0.303 | CA28: 0.13 | CB28: 0 | CC28: 0.985 | CD28: 0.845 | CE28: 0.511 | CF28: 0 | CG28: 2.341 | CH28: 0.48 | CI28: 7.3358 | CJ28: 0.6159 | CK28: 0 | CL28: 0 | CM28: 0 | CN28: 0 | CO28: 0 | CP28: 0 | CQ28: 0 | CR28: 0 | CS28: 0 | CT28: 0 | CU28: 0 | CV28: 0 | CW28: 0 | CX28: 1 | CY28: 0 | CZ28: 0 | DA28: 0 | DB28: 1 | DC28: 1 | DD28: (-93.9352540289497, 36.55499473604166) | DE28: 0.034249051780438855 | DF28: 1.0024556830710116
A29: 1400000US29011960100 | B29: 29 | C29: 011 | D29: 960100 | E29: 218.526 | F29: 29011 | G29: 29011960100 | H29: MO | I29: Missouri | J29: Barton County | K29: Census Tract 9601, Barton County, Missouri | L29: 2986 | M29: 3142 | N29: 208 | O29: 1391 | P29: 1359 | Q29: 91 | R29: 1203 | S29: 490 | T29: 165 | U29: 107 | V29: 364 | W29: 18701 | X29: 2442 | Y29: 280 | Z29: 207 | AA29: 517 | AB29: 712 | AC29: 99 | AD29: 139 | AE29: 9 | AF29: 442 | AG29: 0 | AH29: 197 | AI29: 203 | AJ29: 54 | AK29: 14 | AL29: 115 | AM29: 100 | AN29: 46 | AO29: 6 | AP29: 0.1561 | AQ29: 0.051526 | AR29: 0.075511 | AS29: 0.256754 | AT29: 18701 | AU29: 2442 | AV29: 0.133143 | AW29: 0.097953 | AX29: 0.173141 | AY29: 0.238446 | AZ29: 0.08229426 | BA29: 0.04655 | BB29: 0.003012 | BC29: 0.147924 | BD29: 0 | BE29: 0.144959 | BF29: 0.149374 | BG29: 0.038455 | BH29: 0.011447 | BI29: 0.094027 | BJ29: 0.081766 | BK29: 0.037106 | BL29: 0.002009 | BM29: 0.6 | BN29: 0.566 | BO29: 0.6903 | BP29: 0.485 | BQ29: 2.3413 | BR29: 0.6101 | BS29: 0.754 | BT29: 0.479 | BU29: 0.327 | BV29: 1.56 | BW29: 0.532 | BX29: 0.227 | BY29: 0.451 | BZ29: 0.678 | CA29: 0.323 | CB29: 0 | CC29: 0.816 | CD29: 0.511 | CE29: 0.685 | CF29: 0.443 | CG29: 2.455 | CH29: 0.541 | CI29: 7.0343 | CJ29: 0.5531 | CK29: 0 | CL29: 0 | CM29: 0 | CN29: 0 | CO29: 0 | CP29: 0 | CQ29: 0 | CR29: 0 | CS29: 0 | CT29: 0 | CU29: 0 | CV29: 0 | CW29: 0 | CX29: 0 | CY29: 0 | CZ29: 0 | DA29: 0 | DB29: 0 | DC29: 0 | DD29: (-94.17851253130083, 37.49502617501359) | DE29: 0.058081546691491265 | DF29: 1.1825763
A30: 1400000US29011960200 | B30: 29 | C30: 011 | D30: 960200 | E30: 354.829 | F30: 29011 | G30: 29011960200 | H30: MO | I30: Missouri | J30: Barton County | K30: Census Tract 9602, Barton County, Missouri | L30: 4104 | M30: 4158 | N30: 224 | O30: 1766 | P30: 1786 | Q30: 128 | R30: 1546 | S30: 534 | T30: 179 | U30: 110 | V30: 400 | W30: 19593 | X30: 2302 | Y30: 359 | Z30: 182 | AA30: 586 | AB30: 1158 | AC30: 106 | AD30: 224 | AE30: 62 | AF30: 415 | AG30: 0 | AH30: 197 | AI30: 278 | AJ30: 67 | AK30: 60 | AL30: 120 | AM30: 88 | AN30: 37 | AO30: 0 | AP30: 0.128674 | AQ30: 0.042569 | AR30: 0.058448 | AS30: 0.212465 | AT30: 19593 | AU30: 2302 | AV30: 0.126009 | AW30: 0.063389 | AX30: 0.142787 | AY30: 0.282163 | AZ30: 0.06856403 | BA30: 0.05458 | BB30: 0.016 | BC30: 0.107093 | BD30: 0 | BE30: 0.110302 | BF30: 0.155655 | BG30: 0.035816 | BH30: 0.037313 | BI30: 0.074564 | BJ30: 0.054726 | BK30: 0.022573 | BL30: 0 | BM30: 0.491 | BN30: 0.398 | BO30: 0.6404 | BP30: 0.453 | BQ30: 1.9824 | BR30: 0.4895 | BS30: 0.523 | BT30: 0.856 | BU30: 0.203 | BV30: 1.582 | BW30: 0.553 | BX30: 0.281 | BY30: 0.824 | BZ30: 1.105 | CA30: 0.617 | CB30: 0 | CC30: 0.83 | CD30: 0.876 | CE30: 0.527 | CF30: 0 | CG30: 2.233 | CH30: 0.431 | CI30: 6.9024 | CJ30: 0.5307 | CK30: 0 | CL30: 0 | CM30: 0 | CN30: 0 | CO30: 0 | CP30: 0 | CQ30: 0 | CR30: 0 | CS30: 0 | CT30: 0 | CU30: 0 | CV30: 0 | CW30: 0 | CX30: 0 | CY30: 0 | CZ30: 0 | DA30: 0 | DB30: 0 | DC30: 0 | DD30: (-94.45462855748012, 37.50761856351083) | DE30: 0.094374479 | DF30: 1.2988932259296477
A31: 1400000US29011960300 | B31: 29 | C31: 011 | D31: 960300 | E31: 18.566 | F31: 29011 | G31: 29011960300 | H31: MO | I31: Missouri | J31: Barton County | K31: Census Tract 9603, Barton County, Missouri | L31: 5312 | M31: 5334 | N31: 206 | O31: 2443 | P31: 2473 | Q31: 174 | R31: 2180 | S31: 938 | T31: 274 | U31: 119 | V31: 401 | W31: 18991 | X31: 2206 | Y31: 633 | Z31: 280 | AA31: 1029 | AB31: 1344 | AC31: 257 | AD31: 335 | AE31: 15 | AF31: 442 | AG31: 69 | AH31: 124 | AI31: 173 | AJ31: 99 | AK31: 93 | AL31: 135 | AM31: 203 | AN31: 101 | AO31: 84 | AP31: 0.1799 | AQ31: 0.051916 | AR31: 0.053773 | AS31: 0.181124 | AT31: 18991 | AU31: 2206 | AV31: 0.18634 | AW31: 0.081504 | AX31: 0.193712 | AY31: 0.253012 | AZ31: 0.1178899 | BA31: 0.063064 | BB31: 0.003046 | BC31: 0.089782 | BD31: 0.027901 | BE31: 0.050103 | BF31: 0.069955 | BG31: 0.039728 | BH31: 0.043195 | BI31: 0.062582 | BJ31: 0.094287 | BK31: 0.046135 | BL31: 0.015813 | BM31: 0.675 | BN31: 0.335 | BO31: 0.6715 | BP31: 0.71 | BQ31: 2.3915 | BR31: 0.6274 | BS31: 0.853 | BT31: 0.64 | BU31: 0.655 | BV31: 2.148 | BW31: 0.946 | BX31: 0.33 | BY31: 0.452 | BZ31: 0.782 | CA31: 0.383 | CB31: 0.535 | CC31: 0.649 | CD31: 0.907 | CE31: 0.734 | CF31: 0.658 | CG31: 3.483 | CH31: 0.931 | CI31: 8.8045 | CJ31: 0.8274 | CK31: 0 | CL31: 0 | CM31: 0 | CN31: 0 | CO31: 0 | CP31: 0 | CQ31: 0 | CR31: 0 | CS31: 0 | CT31: 0 | CU31: 0 | CV31: 0 | CW31: 0 | CX31: 0 | CY31: 1 | CZ31: 0 | DA31: 0 | DB31: 1 | DC31: 1 | DD31: (-94.27664614013958, 37.48721823548631) | DE31: 0.0050184848 | DF31: 0.3774946938406599
A32: 1400000US29013070100 | B32: 29 | C32: 013 | D32: 070100 | E32: 277.196 | F32: 29013 | G32: 29013070100 | H32: MO | I32: Missouri | J32: Bates County | K32: Census Tract 701, Bates County, Missouri | L32: 5248 | M32: 5219 | N32: 374 | O32: 2286 | P32: 2219 | Q32: 105 | R32: 2036 | S32: 558 | T32: 181 | U32: 196 | V32: 291 | W32: 19991 | X32: 1767 | Y32: 564 | Z32: 233 | AA32: 885 | AB32: 1333 | AC32: 166 | AD32: 126 | AE32: 8 | AF32: 442 | AG32: 8 | AH32: 114 | AI32: 309 | AJ32: 103 | AK32: 13 | AL32: 115 | AM32: 34 | AN32: 21 | AO32: 73 | AP32: 0.109907 | AQ32: 0.034631 | AR32: 0.085851 | AS32: 0.127187 | AT32: 19991 | AU32: 1767 | AV32: 0.159277 | AW32: 0.065163 | AX32: 0.168635 | AY32: 0.254001 | AZ32: 0.08153241 | BA32: 0.024009 | BB32: 0.001631 | BC32: 0.090167 | BD32: 0.003605 | BE32: 0.051374 | BF32: 0.139251 | BG32: 0.045947 | BH32: 0.006559 | BI32: 0.05802 | BJ32: 0.017154 | BK32: 0.01054 | BL32: 0.01391 | BM32: 0.415 | BN32: 0.655 | BO32: 0.6152 | BP32: 0.606 | BQ32: 2.2912 | BR32: 0.5986 | BS32: 0.725 | BT32: 0.647 | BU32: 0.32 | BV32: 1.692 | BW32: 0.635 | BX32: 0.038 | BY32: 0.361 | BZ32: 0.399 | CA32: 0.161 | CB32: 0.295 | CC32: 0.799 | CD32: 0.376 | CE32: 0.152 | CF32: 0.634 | CG32: 2.256 | CH32: 0.441 | CI32: 6.6382 | CJ32: 0.4816 | CK32: 0 | CL32: 0 | CM32: 0 | CN32: 0 | CO32: 0 | CP32: 0 | CQ32: 0 | CR32: 0 | CS32: 0 | CT32: 0 | CU32: 0 | CV32: 0 | CW32: 0 | CX32: 0 | CY32: 0 | CZ32: 0 | DA32: 0 | DB32: 0 | DC32: 0 | DD32: (-94.23110835923389, 38.347725251817096) | DE32: 0.074371072 | DF32: 1.4382555742780978
A33: 1400000US29013070200 | B33: 29 | C33: 013 | D33: 070200 | E33: 341.777 | F33: 29013 | G33: 29013070200 | H33: MO | I33: Missouri | J33: Bates County | K33: Census Tract 702, Bates County, Missouri | L33: 4411 | M33: 4506 | N33: 305 | O33: 1971 | P33: 1908 | Q33: 87 | R33: 1695 | S33: 782 | T33: 277 | U33: 158 | V33: 306 | W33: 19761 | X33: 1772 | Y33: 424 | Z33: 243 | AA33: 672 | AB33: 1122 | AC33: 112 | AD33: 197 | AE33: 4 | AF33: 442 | AG33: 0 | AH33: 197 | AI33: 301 | AJ33: 68 | AK33: 52 | AL33: 39 | AM33: 44 | AN33: 23 | AO33: 0 | AP33: 0.1751 | AQ33: 0.060845 | AR33: 0.077986 | AS33: 0.150868 | AT33: 19761 | AU33: 1772 | AV33: 0.143437 | AW33: 0.081745 | AX33: 0.152346 | AY33: 0.254364 | AZ33: 0.06607669 | BA33: 0.044661 | BB33: 0.000938 | BC33: 0.103755 | BD33: 0 | BE33: 0.103249 | BF33: 0.157756 | BG33: 0.034905 | BH33: 0.031843 | BI33: 0.023791 | BJ33: 0.026944 | BK33: 0.013973 | BL33: 0 | BM33: 0.664 | BN33: 0.592 | BO33: 0.6303 | BP33: 0.539 | BQ33: 2.4253 | BR33: 0.6404 | BS33: 0.601 | BT33: 0.65 | BU33: 0.182 | BV33: 1.433 | BW33: 0.42 | BX33: 0.21 | BY33: 0.33 | BZ33: 0.54 | CA33: 0.234 | CB33: 0 | CC33: 0.835 | CD33: 0.829 | CE33: 0.258 | CF33: 0 | CG33: 1.922 | CH33: 0.312 | CI33: 6.3203 | CJ33: 0.4332 | CK33: 0 | CL33: 0 | CM33: 0 | CN33: 0 | CO33: 0 | CP33: 0 | CQ33: 0 | CR33: 0 | CS33: 0 | CT33: 0 | CU33: 0 | CV33: 0 | CW33: 0 | CX33: 0 | CY33: 0 | CZ33: 0 | DA33: 0 | DB33: 0 | DC33: 0 | DD33: (-94.50143623150173, 38.2607532267505) | DE33: 0.0925209 | DF33: 1.446619386224154
A34: 1400000US29013070300 | B34: 29 | C34: 013 | D34: 070300 | E34: 11.475 | F34: 29013 | G34: 29013070300 | H34: MO | I34: Missouri | J34: Bates County | K34: Census Tract 703, Bates County, Missouri | L34: 4520 | M34: 4513 | N34: 206 | O34: 2182 | P34: 2219 | Q34: 196 | R34: 1860 | S34: 1071 | T34: 368 | U34: 111 | V34: 433 | W34: 17035 | X34: 1927 | Y34: 508 | Z34: 315 | AA34: 948 | AB34: 1082 | AC34: 212 | AD34: 308 | AE34: 0 | AF34: 456 | AG34: 46 | AH34: 170 | AI34: 63 | AJ34: 46 | AK34: 64 | AL34: 124 | AM34: 174 | AN34: 94 | AO34: 215 | AP34: 0.246376 | AQ34: 0.083442 | AR34: 0.061941 | AS34: 0.241457 | AT34: 17035 | AU34: 1927 | AV34: 0.164454 | AW34: 0.101557 | AX34: 0.209734 | AY34: 0.23938 | AZ34: 0.11397849 | BA34: 0.068141 | BB34: 0 | BC34: 0.110867 | BD34: 0.02073 | BE34: 0.076589 | BF34: 0.028391 | BG34: 0.020577 | BH34: 0.034707 | BI34: 0.067163 | BJ34: 0.09436 | BK34: 0.050174 | BL34: 0.047566 | BM34: 0.82 | BN34: 0.436 | BO34: 0.7841 | BP34: 0.63 | BQ34: 2.6701 | BR34: 0.7119 | BS34: 0.907 | BT34: 0.492 | BU34: 0.621 | BV34: 2.02 | BW34: 0.867 | BX34: 0.354 | BY34: 0 | BZ34: 0.354 | CA34: 0.148 | CB34: 0.471 | CC34: 0.543 | CD34: 0.858 | CE34: 0.735 | CF34: 0.887 | CG34: 3.494 | CH34: 0.935 | CI34: 8.5381 | CJ34: 0.7913 | CK34: 0 | CL34: 0 | CM34: 0 | CN34: 0 | CO34: 0 | CP34: 1 | CQ34: 0 | CR34: 0 | CS34: 1 | CT34: 0 | CU34: 0 | CV34: 0 | CW34: 0 | CX34: 0 | CY34: 0 | CZ34: 0 | DA34: 0 | DB34: 0 | DC34: 1 | DD34: (-94.3362921063866, 38.260407289091575) | DE34: 0.0031006747 | DF34: 0.2816572428573288
A35: 1400000US29013070400 | B35: 29 | C35: 013 | D35: 070400 | E35: 206.241 | F35: 29013 | G35: 29013070400 | H35: MO | I35: Missouri | J35: Bates County | K35: Census Tract 704, Bates County, Missouri | L35: 2870 | M35: 2894 | N35: 302 | O35: 1403 | P35: 1453 | Q35: 83 | R35: 1153 | S35: 507 | T35: 158 | U35: 77 | V35: 303 | W35: 19423 | X35: 1892 | Y35: 450 | Z35: 243 | AA35: 514 | AB35: 717 | AC35: 85 | AD35: 122 | AE35: 3 | AF35: 442 | AG35: 6 | AH35: 161 | AI35: 225 | AJ35: 59 | AK35: 25 | AL35: 116 | AM35: 83 | AN35: 41 | AO35: 23 | AP35: 0.175432 | AQ35: 0.051506 | AR35: 0.059276 | AS35: 0.233136 | AT35: 19423 | AU35: 1892 | AV35: 0.231006 | AW35: 0.123757 | AX35: 0.179094 | AY35: 0.249825 | AZ35: 0.07372072 | BA35: 0.042508 | BB35: 0.001092 | BC35: 0.161019 | BD35: 0.004129 | BE35: 0.110804 | BF35: 0.154852 | BG35: 0.03963 | BH35: 0.021815 | BI35: 0.101206 | BJ35: 0.072425 | BK35: 0.0353 | BL35: 0.008013 | BM35: 0.666 | BN35: 0.407 | BO35: 0.6477 | BP35: 0.829 | BQ35: 2.5497 | BR35: 0.6823 | BS35: 0.782 | BT35: 0.593 | BU35: 0.247 | BV35: 1.622 | BW35: 0.582 | BX35: 0.189 | BY35: 0.336 | BZ35: 0.525 | CA35: 0.225 | CB35: 0.302 | CC35: 0.828 | CD35: 0.707 | CE35: 0.635 | CF35: 0.551 | CG35: 3.023 | CH35: 0.786 | CI35: 7.7197 | CJ35: 0.6736 | CK35: 0 | CL35: 0 | CM35: 0 | CN35: 0 | CO35: 0 | CP35: 0 | CQ35: 0 | CR35: 0 | CS35: 0 | CT35: 0 | CU35: 0 | CV35: 0 | CW35: 0 | CX35: 0 | CY35: 0 | CZ35: 0 | DA35: 0 | DB35: 0 | DC35: 0 | DD35: (-94.22043069570418, 38.1334375787573) | DE35: 0.057007981 | DF35: 1.292216050436748
A36: 1400000US29015460200 | B36: 29 | C36: 015 | D36: 460200 | E36: 112.934 | F36: 29015 | G36: 29015460200 | H36: MO | I36: Missouri | J36: Benton County | K36: Census Tract 4602, Benton County, Missouri | L36: 2466 | M36: 2688 | N36: 340 | O36: 1128 | P36: 1169 | Q36: 93 | R36: 989 | S36: 706 | T36: 230 | U36: 107 | V36: 399 | W36: 16126 | X36: 2203 | Y36: 376 | Z36: 273 | AA36: 537 | AB36: 595 | AC36: 86 | AD36: 91 | AE36: 6 | AF36: 442 | AG36: 3 | AH36: 161 | AI36: 95 | AJ36: 54 | AK36: 14 | AL36: 115 | AM36: 59 | AN36: 44 | AO36: 58 | AP36: 0.273537 | AQ36: 0.083166 | AR36: 0.106573 | AS36: 0.396842 | AT36: 16126 | AU36: 2203 | AV36: 0.207276 | AW36: 0.148323 | AX36: 0.217761 | AY36: 0.241281 | AZ36: 0.08695652 | BA36: 0.036901 | BB36: 0.002442 | BC36: 0.179967 | BD36: 0.002566 | BE36: 0.137724 | BF36: 0.081266 | BG36: 0.045738 | BH36: 0.01327 | BI36: 0.108998 | BJ36: 0.055924 | BK36: 0.041401 | BL36: 0.023519 | BM36: 0.862 | BN36: 0.77 | BO36: 0.8303 | BP36: 0.774 | BQ36: 3.2363 | BR36: 0.8628 | BS36: 0.927 | BT36: 0.506 | BU36: 0.376 | BV36: 1.809 | BW36: 0.728 | BX36: 0.135 | BY36: 0.407 | BZ36: 0.542 | CA36: 0.236 | CB36: 0.279 | CC36: 0.677 | CD36: 0.556 | CE36: 0.541 | CF36: 0.752 | CG36: 2.805 | CH36: 0.691 | CI36: 8.3923 | CJ36: 0.7726 | CK36: 0 | CL36: 0 | CM36: 0 | CN36: 0 | CO36: 0 | CP36: 1 | CQ36: 0 | CR36: 0 | CS36: 1 | CT36: 0 | CU36: 0 | CV36: 0 | CW36: 0 | CX36: 0 | CY36: 0 | CZ36: 0 | DA36: 0 | DB36: 0 | DC36: 1 | DD36: (-93.40055504640561, 38.43999349085813) | DE36: 0.030261068 | DF36: 0.82937206
A37: 1400000US29015460300 | B37: 29 | C37: 015 | D37: 460300 | E37: 67.292 | F37: 29015 | G37: 29015460300 | H37: MO | I37: Missouri | J37: Benton County | K37: Census Tract 4603, Benton County, Missouri | L37: 4378 | M37: 4080 | N37: 371 | O37: 2581 | P37: 2581 | Q37: 114 | R37: 1917 | S37: 674 | T37: 254 | U37: 117 | V37: 384 | W37: 20395 | X37: 2325 | Y37: 681 | Z37: 276 | AA37: 1166 | AB37: 835 | AC37: 161 | AD37: 223 | AE37: 0 | AF37: 456 | AG37: 0 | AH37: 197 | AI37: 358 | AJ37: 102 | AK37: 32 | AL37: 32 | AM37: 143 | AN37: 79 | AO37: 115 | AP37: 0.171632 | AQ37: 0.062476 | AR37: 0.072942 | AS37: 0.239146 | AT37: 20395 | AU37: 2325 | AV37: 0.217989 | AW37: 0.086391 | AX37: 0.266331 | AY37: 0.190726 | AZ37: 0.08398539 | BA37: 0.050936 | BB37: 0 | BC37: 0.11518 | BD37: 0 | BE37: 0.076327 | BF37: 0.138705 | BG37: 0.039041 | BH37: 0.017316 | BI37: 0.017252 | BJ37: 0.07738 | BK37: 0.042233 | BL37: 0.026267 | BM37: 0.65 | BN37: 0.538 | BO37: 0.5884 | BP37: 0.797 | BQ37: 2.5734 | BR37: 0.6924 | BS37: 0.979 | BT37: 0.152 | BU37: 0.35 | BV37: 1.481 | BW37: 0.466 | BX37: 0.251 | BY37: 0 | BZ37: 0.251 | CA37: 0.108 | CB37: 0 | CC37: 0.795 | CD37: 0.633 | CE37: 0.658 | CF37: 0.782 | CG37: 2.868 | CH37: 0.719 | CI37: 7.1734 | CJ37: 0.5848 | CK37: 0 | CL37: 0 | CM37: 0 | CN37: 0 | CO37: 0 | CP37: 1 | CQ37: 0 | CR37: 0 | CS37: 1 | CT37: 0 | CU37: 0 | CV37: 0 | CW37: 0 | CX37: 0 | CY37: 0 | CZ37: 0 | DA37: 0 | DB37: 0 | DC37: 1 | DD37: (-93.3965342055821, 38.32458422566202) | DE37: 0.020190378957370258 | DF37: 0.7769681567473826
A38: 1400000US29015460400 | B38: 29 | C38: 015 | D38: 460400 | E38: 83.533 | F38: 29015 | G38: 29015460400 | H38: MO | I38: Missouri | J38: Benton County | K38: Census Tract 4604, Benton County, Missouri | L38: 2269 | M38: 2124 | N38: 299 | O38: 2373 | P38: 2241 | Q38: 139 | R38: 1066 | S38: 328 | T38: 171 | U38: 70 | V38: 473 | W38: 16449 | X38: 2266 | Y38: 369 | Z38: 291 | AA38: 653 | AB38: 322 | AC38: 54 | AD38: 80 | AE38: 0 | AF38: 456 | AG38: 0 | AH38: 197 | AI38: 474 | AJ38: 150 | AK38: 73 | AL38: 127 | AM38: 74 | AN38: 66 | AO38: 4 | AP38: 0.154425 | AQ38: 0.077517 | AR38: 0.10558 | AS38: 0.711052 | AT38: 16449 | AU38: 2266 | AV38: 0.20297 | AW38: 0.157158 | AX38: 0.287791 | AY38: 0.141912 | AZ38: 0.05065666 | BA38: 0.035257 | BB38: 0 | BC38: 0.214689 | BD38: 0 | BE38: 0.087907 | BF38: 0.211512 | BG38: 0.065636 | BH38: 0.073514 | BI38: 0.127366 | BJ38: 0.074521 | BK38: 0.065412 | BL38: 0.001762 | BM38: 0.593 | BN38: 0.766 | BO38: 0.8152 | BP38: 0.758 | BQ38: 2.9322 | BR38: 0.7892 | BS38: 0.984 | BT38: 0.054 | BU38: 0.076 | BV38: 1.114 | BW38: 0.176 | BX38: 0.122 | BY38: 0 | BZ38: 0.122 | CA38: 0.058 | CB38: 0 | CC38: 0.912 | CD38: 0.981 | CE38: 0.646 | CF38: 0.435 | CG38: 2.974 | CH38: 0.764 | CI38: 7.1422 | CJ38: 0.5776 | CK38: 0 | CL38: 0 | CM38: 0 | CN38: 0 | CO38: 0 | CP38: 1 | CQ38: 0 | CR38: 0 | CS38: 1 | CT38: 0 | CU38: 0 | CV38: 0 | CW38: 0 | CX38: 1 | CY38: 1 | CZ38: 0 | DA38: 0 | DB38: 2 | DC38: 3 | DD38: (-93.17772301729, 38.306048245489116) | DE38: 0.023465643 | DF38: 0.8089296349524091
A39: 1400000US29015460700 | B39: 29 | C39: 015 | D39: 460700 | E39: 95.449 | F39: 29015 | G39: 29015460700 | H39: MO | I39: Missouri | J39: Benton County | K39: Census Tract 4607, Benton County, Missouri | L39: 2821 | M39: 2649 | N39: 426 | O39: 3272 | P39: 3073 | Q39: 170 | R39: 1368 | S39: 435 | T39: 220 | U39: 51 | V39: 487 | W39: 24278 | X39: 4254 | Y39: 567 | Z39: 319 | AA39: 925 | AB39: 320 | AC39: 52 | AD39: 87 | AE39: 0 | AF39: 456 | AG39: 38 | AH39: 169 | AI39: 924 | AJ39: 185 | AK39: 23 | AL39: 120 | AM39: 12 | AN39: 116 | AO39: 10 | AP39: 0.164212 | AQ39: 0.078739 | AR39: 0.053125 | AS39: 0.50682 | AT39: 24278 | AU39: 4254 | AV39: 0.240764 | AW39: 0.130893 | AX39: 0.327897 | AY39: 0.113434 | AZ39: 0.03801169 | BA39: 0.03084 | BB39: 0 | BC39: 0.173449 | BD39: 0.012365 | BE39: 0.05499 | BF39: 0.300683 | BG39: 0.057858 | BH39: 0.017189 | BI39: 0.089648 | BJ39: 0.008968 | BK39: 0.086686 | BL39: 0.003544 | BM39: 0.624 | BN39: 0.325 | BO39: 0.3819 | BP39: 0.848 | BQ39: 2.1789 | BR39: 0.5574 | BS39: 0.993 | BT39: 0.033 | BU39: 0.032 | BV39: 1.058 | BW39: 0.14 | BX39: 0.085 | BY39: 0 | BZ39: 0.085 | CA39: 0.04 | CB39: 0.403 | CC39: 0.981 | CD39: 0.633 | CE39: 0.076 | CF39: 0.488 | CG39: 2.581 | CH39: 0.596 | CI39: 5.9029 | CJ39: 0.3552 | CK39: 0 | CL39: 0 | CM39: 0 | CN39: 0 | CO39: 0 | CP39: 1 | CQ39: 0 | CR39: 0 | CS39: 1 | CT39: 0 | CU39: 0 | CV39: 0 | CW39: 0 | CX39: 1 | CY39: 0 | CZ39: 0 | DA39: 0 | DB39: 1 | DC39: 2 | DD39: (-93.43886450665872, 38.18514012104636) | DE39: 0.032949907 | DF39: 1.0176688940941083
